<mujoco model="humanoid">
    <actuator>
        <motor ctrllimited="true" ctrlrange="-50.0 50.0" name="left_j1_T" joint="left_j1" />
        <motor ctrllimited="true" ctrlrange="-50.0 50.0" name="left_j2_T" joint="left_j2" />
        <motor ctrllimited="true" ctrlrange="-50.0 50.0" name="left_j3_T" joint="left_j3" />
        <motor ctrllimited="true" ctrlrange="-50.0 50.0" name="left_j4_T" joint="left_j4" />
        <motor ctrllimited="true" ctrlrange="-50.0 50.0" name="left_j5_T" joint="left_j5" />
        <motor ctrllimited="true" ctrlrange="-50.0 50.0" name="left_j6_T" joint="left_j6" />
        <motor ctrllimited="true" ctrlrange="-50.0 50.0" name="left_j7_T" joint="left_j7" />
    </actuator>

<!--    <option impratio="20" cone="elliptic" density="1.2" viscosity="0.00002" timestep="0.002"/>-->

<!--    <default>-->
<!--        <geom density="5.0"/>-->
<!--        <default class="arm_joint">-->
<!--            <joint axis="1 0 0" range="-3.14 3.14" damping="2" limited="true" armature="0.0002" frictionloss="0.01"/>-->
<!--            <position kp="3" ctrlrange="-3.14 3.14"/>-->
<!--        </default>-->
<!--        <default class="joint">-->
<!--            <joint axis="1 0 0" range="-3.14 3.14" damping="1" limited="true" armature="0.0002" frictionloss="0.01"/>-->
<!--            <position kp="3" ctrlrange="-2 2"/>-->
<!--        </default>-->
<!--    </default>-->

<!--    <size njmax="500" nconmax="100"/>-->
    <asset>
<!--        <texture builtin="gradient" height="100" rgb1=".4 .5 .6" rgb2="0 0 0" type="skybox" width="100"/>-->
<!--        <texture name="texplane" type="2d" builtin="checker" rgb1=".2 .3 .4" rgb2=".1 0.15 0.2" width="100" height="100"/>-->
<!--        <material name="MatPlane" reflectance="0.5" texture="texplane" texrepeat="1 1" texuniform="true"/>-->

<!--        <texture file="/home/kavin/anaconda3/envs/PythonEnv/lib/python3.8/site-packages/robosuite/models/assets/arenas/../textures/ceramic.png" type="cube" name="tex-ceramic"/>-->
<!--        <material name="table_ceramic" reflectance="0.0" shininess="0.0" specular="0.2" texrepeat="1 1" texture="tex-ceramic"/>-->

<!--        <texture file="/home/kavin/anaconda3/envs/PythonEnv/lib/python3.8/site-packages/robosuite/models/assets/arenas/../textures/steel-brushed.png" type="cube" name="tex-steel-brushed"/>-->
<!--        <material name="table_legs_metal" reflectance="0.8" shininess="0.8" texrepeat="1 1" texture="tex-steel-brushed"/>-->

<!--        <texture name="textable" builtin="flat" height="512" width="512" rgb1="0.5 0.5 0.5" rgb2="0.5 0.5 0.5"/>-->
<!--        <material name="table_mat" texture="textable"/>-->
<!--        <mesh name="mount0_pedestal" file="/home/kavin/anaconda3/envs/PythonEnv/lib/python3.8/site-packages/robosuite/models/assets/mounts/meshes/rethink_mount/pedestal.stl"/>-->

<!--        <mesh file="/home/kavin/Documents/PycharmProjects/Mujoco/hand_imitation/utils/../models/assets/ycb/collision/011_banana/011_banana_1.stl" name="banana_collision_mesh_1" scale="0.8 0.8 0.8"/>-->
<!--        <mesh file="/home/kavin/Documents/PycharmProjects/Mujoco/hand_imitation/utils/../models/assets/ycb/collision/011_banana/011_banana_2.stl" name="banana_collision_mesh_2" scale="0.8 0.8 0.8"/>-->
<!--        <mesh file="/home/kavin/Documents/PycharmProjects/Mujoco/hand_imitation/utils/../models/assets/ycb/visual/011_banana/textured_simple_blender.msh" name="banana_visual_mesh"-->
<!--              scale="0.8 0.8 0.8"/>-->
<!--        <texture file="/home/kavin/Documents/PycharmProjects/Mujoco/hand_imitation/utils/../models/assets/ycb/visual/011_banana/texture_map.png" name="banana_texture" type="2d"/>-->
<!--        <material name="banana_material" texture="banana_texture"/>-->

<!--        <mesh file="/home/kavin/Documents/GitProjects/RL/robosuite/robosuite/models/assets/objects/meshes/can.msh" name="can_mesh"/>-->
<!--        <texture file="/home/kavin/Documents/GitProjects/RL/robosuite/robosuite/models/assets/textures/soda.png" name="tex-can" type="2d"/>-->
<!--        <material name="coke" reflectance="0.7" texrepeat="5 5" texture="tex-can" texuniform="true"/>-->

<!--        <texture type="cube" name="cube_redwood" file="/home/kavin/Documents/PycharmProjects/Robosuite/robosuite/models/assets/textures/red-wood.png" />-->
<!--        <material texrepeat="1 1" specular="0.4" shininess="0.1" name="cube_redwood_mat" texture="cube_redwood" />-->

        <mesh name="body" file="meshes/body.STL"/>
        <mesh name="neck" file="meshes/neck.STL"/>
        <mesh name="head" file="meshes/head.STL"/>
        <mesh name="left_1" file="meshes/left_1.STL"/>
        <mesh name="left_2" file="meshes/left_2.STL"/>
        <mesh name="left_3" file="meshes/left_3.STL"/>
        <mesh name="left_4" file="meshes/left_4.STL"/>
        <mesh name="left_5" file="meshes/left_5.STL"/>
        <mesh name="left_6" file="meshes/left_6.STL"/>
        <mesh name="left_7" file="meshes/left_7.STL"/>

        <mesh name="right_1" file="meshes/right_1.STL"/>
        <mesh name="right_2" file="meshes/right_2.STL"/>
        <mesh name="right_3" file="meshes/right_3.STL"/>
        <mesh name="right_4" file="meshes/right_4.STL"/>
        <mesh name="right_5" file="meshes/right_5.STL"/>
        <mesh name="right_6" file="meshes/right_6.STL"/>

<!--        <mesh name="palm_left" file="meshes/palm_left.STL" />-->
<!--        <mesh name="finger_11_left" file="meshes/robot/finger_11_left.STL" />-->
<!--        <mesh name="finger_12_left" file="meshes/robot/finger_12_left.STL" />-->
<!--        <mesh name="finger_13_left" file="meshes/robot/finger_13_left.STL" />-->
<!--        <mesh name="finger_14_left" file="meshes/robot/finger_14_left.STL" />-->
<!--        <mesh name="finger_21_left" file="meshes/robot/finger_21_left.STL" />-->
<!--        <mesh name="finger_22_left" file="meshes/robot/finger_22_left.STL" />-->
<!--        <mesh name="finger_23_left" file="meshes/robot/finger_23_left.STL" />-->
<!--        <mesh name="finger_31_left" file="meshes/robot/finger_31_left.STL" />-->
<!--        <mesh name="finger_32_left" file="meshes/robot/finger_32_left.STL" />-->
<!--        <mesh name="finger_33_left" file="meshes/robot/finger_33_left.STL" />-->
<!--        <mesh name="finger_41_left" file="meshes/robot/finger_41_left.STL" />-->
<!--        <mesh name="finger_42_left" file="meshes/robot/finger_42_left.STL" />-->
<!--        <mesh name="finger_43_left" file="meshes/robot/finger_43_left.STL" />-->
<!--        <mesh name="finger_51_left" file="meshes/robot/finger_51_left.STL" />-->
<!--        <mesh name="finger_52_left" file="meshes/robot/finger_52_left.STL" />-->
<!--        <mesh name="finger_53_left" file="meshes/robot/finger_53_left.STL" />-->

        <mesh name="palm_right" file="meshes/palm_right.STL" />
        <mesh name="finger_11_right" file="meshes/finger_11_right.STL" />
        <mesh name="finger_12_right" file="meshes/finger_12_right.STL" />
        <mesh name="finger_13_right" file="meshes/finger_13_right.STL" />
        <mesh name="finger_14_right" file="meshes/finger_14_right.STL" />
        <mesh name="finger_21_right" file="meshes/finger_21_right.STL" />
        <mesh name="finger_22_right" file="meshes/finger_22_right.STL" />
        <mesh name="finger_23_right" file="meshes/finger_23_right.STL" />
        <mesh name="finger_31_right" file="meshes/finger_31_right.STL" />
        <mesh name="finger_32_right" file="meshes/finger_32_right.STL" />
        <mesh name="finger_33_right" file="meshes/finger_33_right.STL" />
        <mesh name="finger_41_right" file="meshes/finger_41_right.STL" />
        <mesh name="finger_42_right" file="meshes/finger_42_right.STL" />
        <mesh name="finger_43_right" file="meshes/finger_43_right.STL" />
        <mesh name="finger_51_right" file="meshes/finger_51_right.STL" />
        <mesh name="finger_52_right" file="meshes/finger_52_right.STL" />
        <mesh name="finger_53_right" file="meshes/finger_53_right.STL" />
    </asset>

    <worldbody>
<!--        <geom name="floor" pos="0 0 0" size="10 10 0.125" type="plane" material="MatPlane" condim="3" group="2" rgba="0.8 0.9 0.8 1"/>-->
<!--        <light cutoff="100" diffuse="1 1 1" dir="-0 0 -1.3" directional="true" exponent="1" pos="0 0 1.3" specular=".1 .1 .1" castshadow="false"/>-->
<!--        <body name="table" pos="0.0 0.0 0.775">-->
<!--            <geom pos="0 0 0" size="0.4 0.4 0.025" type="box" group="0" name="table_collision" friction="1.0 0.005 0.0001" rgba="0.5 0.5 0 1"/>-->
<!--            <geom pos="0 0 0" size="0.4 0.4 0.025" type="box" conaffinity="0" contype="0" group="1" name="table_visual" material="table_ceramic"/>-->
<!--            <site pos="0.0 0.0 0.025" name="table_top" size="0.001 0.001 0.001" rgba="0 0 0 0"/>-->

<!--            <geom pos="0.3 0.3 -0.3875" size="0.025 0.3875" type="cylinder" conaffinity="0" contype="0" group="1" name="table_leg1_visual" material="table_legs_metal"/>-->
<!--            <geom pos="-0.3 0.3 -0.3875" size="0.025 0.3875" type="cylinder" conaffinity="0" contype="0" group="1" name="table_leg2_visual" material="table_legs_metal"/>-->
<!--            <geom pos="-0.3 -0.3 -0.3875" size="0.025 0.3875" type="cylinder" conaffinity="0" contype="0" group="1" name="table_leg3_visual" material="table_legs_metal"/>-->
<!--            <geom pos="0.3 -0.3 -0.3875" size="0.025 0.3875" type="cylinder" conaffinity="0" contype="0" group="1" name="table_leg4_visual" material="table_legs_metal"/>-->
<!--        </body>-->
<!--        <body name="banana_0" pos="0 0.1 1." quat="0.707 0 0 0.707">-->
<!--            <geom type="mesh" mesh="banana_collision_mesh_1" name="collision_banana_1" density="1000" group="2" friction="1 0.5 0.01" condim="4"/>-->
<!--            <geom type="mesh" mesh="banana_collision_mesh_2" name="collision_banana_2" density="1000" group="2" friction="1 0.5 0.01" condim="4"/>-->
<!--            <geom mesh="banana_visual_mesh" group="1" type="mesh" contype="0" conaffinity="0" material="banana_material"/>-->
<!--            <joint type="free" name="banana_joint_0" limited="false" damping="0" frictionloss="0.001" armature="0.001"/>-->
<!--        </body>-->
<!--        <body name="object" pos="0.05 0.1 0.9">-->
<!--            <geom pos="0 0 0" mesh="can_mesh" type="mesh" solimp="0.998 0.998 0.001" solref="0.001 1" density="100" friction="0.95 0.95 0.1" material="coke" group="0" condim="4"/>-->
<!--            <joint type="free" name="obj_joint0" />-->
<!--        </body>-->
<!--        <body name="cube_main" pos="0 0.2 1.">-->
<!--            <geom rgba="0.5 0 0 1" density="1000" friction="1 0.005 0.0001" solref="0.02 1.0" solimp="0.9 0.95 0.001" type="box" size="0.02113568705286487 0.020345870746550553 0.02025985026685403" pos="0 0 0" group="0" name="cube_g0" />-->
<!--            <geom conaffinity="0" contype="0" mass="1" material="cube_redwood_mat" type="box" size="0.02113568705286487 0.020345870746550553 0.02025985026685403" pos="0 0 0" group="1" name="cube_g0_vis" />-->
<!--            <joint type="free" name="cube_joint0" />-->
<!--            <site type="sphere" group="0" pos="0 0 0" size="0.002 0.002 0.002" rgba="1 0 0 1" name="cube_default_site" />-->
<!--        </body>-->
<!--        <camera name="frontview" pos="1.8 0 0.65" quat="0.560842 0.430646 0.430646 0.560842"/>-->
<!--        <camera name="birdview" pos="-0.2 0 3" quat="0.707107 0 0 0.707107"/>-->
        <body name="body" pos="0 0 0.3">
<!--            <site name="b_z" type="cylinder" size="0.004 0.4" rgba="0 0 1 1" pos="0 0 0.4"  quat="1 0 0 0"/>-->
<!--            <site name="b_y" type="cylinder" size="0.004 0.4" rgba="0 1 0 1" pos="0 0.4 0" quat="0.707 0.707 0 0"/>-->
<!--            <site name="b_x" type="cylinder" size="0.004 0.4" rgba="1 0 0 1" pos="0.4 0 0" quat="0.707 0 0.707 0"/>-->
            <inertial pos="0 0 0" quat="0.5 0.5 -0.5 0.5" mass="4" diaginertia="0.0072 0.00443333 0.00443333"/>
            <geom type="mesh" contype="0" conaffinity="0" group="1" rgba="0.792157 0.819608 0.933333 1" mesh="body" name="body_visual"/>
            <geom type="mesh" rgba="0.792157 0.819608 0.933333 1" mesh="body" name="body_collision"/>
            <body name="left_1" pos="0.0084368 0.13751 0.43" quat="0.422014 0.509768 -0.577484 -0.478073">
                <inertial pos="-0.0389123 -8.15098e-11 4.37584e-11" quat="0.707107 0 0 0.707107" mass="0.450915" diaginertia="0.00114268 0.000950117 0.000939472"/>
                <joint name="left_j1" axis="1 0 0" limited="true" range="-3.14 3.14" damping="0.001" frictionloss="0.01" />
                <geom type="mesh" contype="0" conaffinity="0" group="1" rgba="0.792157 0.819608 0.933333 1" mesh="left_1" name="left_1_visual"/>
                <geom type="mesh" rgba="0.792157 0.819608 0.933333 1" mesh="left_1" />
                <body name="left_2" pos="-0.075 0 0" quat="0.934134 0 -0.356921 0">
                    <inertial pos="-0.0621308 1.25597e-07 0.00042437" quat="3.21075e-06 0.706526 3.20548e-06 0.707688" mass="1.56019" diaginertia="0.00710312 0.00597558 0.00259922"/>
                    <joint name="left_j2" axis="0 1 0" limited="true" range="-1. 1.57" damping="1" frictionloss="0.01" />
                    <geom type="mesh" contype="0" conaffinity="0" group="1" rgba="0.792157 0.819608 0.933333 1" mesh="left_2" name="left_2_visual"/>
                    <geom type="mesh" rgba="0.792157 0.819608 0.933333 1" mesh="left_2" name="left_2_collision"/>
                    <body name="left_3" pos="-0.16 0 0" quat="0.792164 0.610309 0 0">
                        <inertial pos="-0.059665 2.14069e-07 -0.000729859" quat="0.502955 0.497027 0.497027 0.502955" mass="0.52034" diaginertia="0.00128574 0.00107323 0.000678269"/>
                        <joint name="left_j3" axis="1 0 0" limited="true" range="-3.14 3.14" damping="1" frictionloss="0.01" />
                        <geom type="mesh" contype="0" conaffinity="0" group="1" rgba="0.792157 0.819608 0.933333 1" mesh="left_3" name="left_3_visual"/>
                        <geom type="mesh" rgba="0.792157 0.819608 0.933333 1" mesh="left_3" name="left_3_collision"/>
                        <body name="left_4" pos="-0.121 0 0.037" quat="0.854816 0 0 0.518931">
                            <inertial pos="-0.0236502 -1.38379e-09 -0.037" quat="0.5 0.5 0.5 0.5" mass="0.187003" diaginertia="0.000176801 0.00013087 0.000111406"/>
                            <joint name="left_j4" axis="0 0 -1" limited="true" range="-0.8 3." damping="1" frictionloss="0.01" />
                            <geom type="mesh" contype="0" conaffinity="0" group="1" rgba="0.792157 0.819608 0.933333 1" mesh="left_4" name="left_4_visual"/>
                            <geom type="mesh" rgba="0.792157 0.819608 0.933333 1" mesh="left_4" name="left_4_collision"/>
                            <body name="left_5" pos="-0.058 0 -0.037" quat="0.184654 -0.982804 0 0">
                                <inertial pos="-0.118694 -2.89295e-08 1.30138e-07" quat="0.499999 0.500001 0.500001 0.499999" mass="1.41911" diaginertia="0.00746362 0.00730999 0.00143555"/>
                                <joint name="left_j5" axis="1 0 0" limited="true" range="-3.14 3.14" damping="1" frictionloss="0.01"/>
                                <geom type="mesh" contype="0" conaffinity="0" group="1" rgba="0.792157 0.819608 0.933333 1" mesh="left_5" name="left_5_visual"/>
                                <geom type="mesh" rgba="0.792157 0.819608 0.933333 1" mesh="left_5" name="left_5_collision"/>
                                <body name="left_6" pos="-0.250811 0 0.025" quat="0.108969 0 0 0.994045">
                                    <inertial pos="0.00125752 -0.0001315 -0.0250062" quat="0.036822 0.70613 -0.0368186 0.706165" mass="0.130726" diaginertia="6.86601e-05 5.37786e-05 4.85598e-05"/>
                                    <joint name="left_j6" axis="0 0 -1" limited="true" range="-1. 1." damping="1" frictionloss="0.01" />
                                    <geom type="mesh" contype="0" conaffinity="0" group="1" rgba="0.792157 0.819608 0.933333 1" mesh="left_6" name="left_6_visual"/>
                                    <geom type="mesh" rgba="0.792157 0.819608 0.933333 1" mesh="left_6" name="left_6_collision"/>
                                    <body name="left_7" pos="0.0457505 -0.00478427 -0.025" quat="0.997782 0.041459 -0.00216185 -0.0520287">
                                        <inertial pos="-0.00442721 0 0" mass="0.0053794" diaginertia="4.8315e-07 2.91425e-07 2.91425e-07"/>
                                        <joint name="left_j7" axis="1 0 0" limited="true" range="-1.57 1.57" damping="1" frictionloss="0.01" />
                                        <geom type="mesh" contype="0" conaffinity="0" group="1" rgba="0.792157 0.819608 0.933333 1" mesh="left_7" name="left_7_visual"/>
                                        <geom type="mesh" rgba="0.792157 0.819608 0.933333 1" mesh="left_7" name="left_7_collision"/>
                                        <body name="left_hand" pos="0 0 0" quat="0.707107 0 0.707107 0">
                                            <camera mode="fixed" name="eye_in_hand" pos="0.05 0 0" quat="0 0.707108 0.707108 0" fovy="75"/>
                                        </body>
                                    </body>
                                </body>
                            </body>
                        </body>
                    </body>
                </body>
            </body>
            <body name="right_1" pos="0.0084368 -0.13751 0.43" quat="0.48055 0.575421 -0.50795 -0.424203">
                <inertial pos="0.0389123 1.82654e-10 -1.72699e-10" quat="0.707107 0 0 0.707107" mass="0.450915" diaginertia="0.00114268 0.000950117 0.000939472"/>
<!--                <joint class="arm_joint" name="right_j1" axis="-1 0 0"/>-->
                <geom type="mesh" contype="0" conaffinity="0" group="1" rgba="0.792157 0.819608 0.933333 1" mesh="right_1"/>
                <geom type="mesh" rgba="0.792157 0.819608 0.933333 1" mesh="right_1" />
                <body name="right_2" pos="0.075 0 0" quat="0.952069 0 0.305882 0">
                    <inertial pos="0.0621308 -1.05439e-07 0.000424393" quat="-4.66413e-06 0.707687 -4.6718e-06 0.706526" mass="1.56018" diaginertia="0.00710311 0.00597557 0.00259921"/>
<!--                    <joint class="arm_joint" name="right_j2" axis="0 -1 0"/>-->
                    <geom type="mesh" contype="0" conaffinity="0" group="1" rgba="0.792157 0.819608 0.933333 1" mesh="right_2"/>
                    <geom type="mesh" rgba="0.792157 0.819608 0.933333 1" mesh="right_2"/>
                    <body name="right_3" pos="0.16 0 0" quat="0.656844 -0.754026 0 0">
                        <inertial pos="0.059665 -2.31924e-09 -0.000729475" quat="0.497027 0.502955 0.502955 0.497027" mass="0.520345" diaginertia="0.00128574 0.00107323 0.000678269"/>
<!--                        <joint class="arm_joint" name="right_j3" axis="-1 0 0"/>-->
                        <geom type="mesh" contype="0" conaffinity="0" group="1" rgba="0.792157 0.819608 0.933333 1" mesh="right_3"/>
                        <geom type="mesh" rgba="0.792157 0.819608 0.933333 1" mesh="right_3"/>
                        <body name="right_4" pos="0.121 0 0.037" quat="0.735818 0 0 -0.677179">
                            <inertial pos="-0.0224102 0.00755756 -0.037" quat="0.574359 0.574359 0.412445 0.412445" mass="0.187003" diaginertia="0.000176801 0.00013087 0.000111406"/>
<!--                            <joint class="arm_joint" name="right_j4" axis="0 0 1"/>-->
                            <geom type="mesh" contype="0" conaffinity="0" group="1" rgba="0.792157 0.819608 0.933333 1" mesh="right_4"/>
                            <geom type="mesh" rgba="0.792157 0.819608 0.933333 1" mesh="right_4"/>
                            <body name="right_5" pos="-0.0549589 0.0185342 -0.037" quat="0.161794 0.00622882 0.0379623 0.986074">
                                <inertial pos="0.118694 -2.00275e-08 -1.32429e-07" quat="0.499999 0.500001 0.500001 0.499999" mass="1.41911" diaginertia="0.00746362 0.00730999 0.00143555"/>
<!--                                <joint class="arm_joint" name="right_j5" axis="-1 0 0"/>-->
                                <geom type="mesh" contype="0" conaffinity="0" group="1" rgba="0.792157 0.819608 0.933333 1" mesh="right_5"/>
                                <geom type="mesh" rgba="0.792157 0.819608 0.933333 1" mesh="right_5"/>
                                <body name="right_6" pos="0.250811 0 0.025" quat="0.992728 0 0 0.120383">
                                    <inertial pos="0.00126437 -1.92791e-09 -0.0249938" quat="1.90734e-06 0.707124 -3.46495e-07 0.707089" mass="0.130726" diaginertia="6.86601e-05 5.37786e-05 4.85598e-05"/>
<!--                                    <joint class="arm_joint" name="right_j6" axis="0 0 1"/>-->
                                    <geom type="mesh" contype="0" conaffinity="0" group="1" rgba="0.792157 0.819608 0.933333 1" mesh="right_6"/>
                                    <geom type="mesh" rgba="0.792157 0.819608 0.933333 1" mesh="right_6"/>
                                    <body name="right_hand" pos="0.04 0 -0.025" quat="0.707107 0 0.707107 0">
                                        <inertial pos="0 0 0" mass="0.01" diaginertia="0.001 0.001 0.001"/>
<!--                                            <joint class="arm_joint" name="right_j7" axis="0 0 -1"/>-->
                                        <geom type="mesh" contype="0" conaffinity="0" group="1" rgba="0.792157 0.819608 0.933333 1" mesh="palm_right" />
                                        <geom type="mesh" rgba="0.792157 0.819608 0.933333 1" mesh="palm_right" />
                                        <body name="finger_11_right" pos="-0.033156 0 0.046854" quat="-0.016518 0.473908 -0.0306641 -0.879885">
                                            <inertial pos="0 0 0.00296384" quat="0.707107 0 0 0.707107" mass="0.00158261" diaginertia="6.47978e-08 5.66929e-08 5.56708e-08" />
<!--                                                <joint class="joint" name="j_11_right" />-->
                                            <geom type="mesh" contype="0" conaffinity="0" group="1" rgba="0.792157 0.819608 0.933333 1" mesh="finger_11_right" />
                                            <geom type="mesh" rgba="0.792157 0.819608 0.933333 1" mesh="finger_11_right" />
                                            <body name="finger_12_right" pos="0 0 0.005" quat="0.997871 0 0 -0.0652237">
                                                <inertial pos="3.05329e-11 9.19322e-11 0.00925016" quat="0.707107 0 0 0.707107" mass="0.00237615" diaginertia="1.18675e-07 1.15819e-07 1.06634e-07" />
<!--                                                    <joint class="joint" name="j_12_right" axis="0 0 -1" />-->
                                                <geom type="mesh" contype="0" conaffinity="0" group="1" rgba="0.792157 0.819608 0.933333 1" mesh="finger_12_right" />
                                                <geom type="mesh" rgba="0.792157 0.819608 0.933333 1" mesh="finger_12_right" />
                                                <body name="finger_13_right" pos="0 0 0.0175" quat="0.998171 0.0604581 0 0">
                                                    <inertial pos="3.32826e-08 -2.58391e-07 0.0134786" quat="0.70734 -4.62782e-06 4.62477e-06 0.706874" mass="0.00477507" diaginertia="5.13037e-07 5.06539e-07 1.11818e-07" />
<!--                                                        <joint class="joint" name="j_13_right" />-->
                                                    <geom type="mesh" contype="0" conaffinity="0" group="1" rgba="0.792157 0.819608 0.933333 1" mesh="finger_13_right" />
                                                    <geom type="mesh" rgba="0.792157 0.819608 0.933333 1" mesh="finger_13_right" />
                                                    <body name="finger_14_right" pos="0 0 0.027" quat="0.999977 0.00681395 0 0">
                                                        <inertial pos="1.25821e-05 -0.000148496 0.0147394" quat="0.704726 0.00742858 -0.00610786 0.709414" mass="0.00459559" diaginertia="3.58607e-07 3.47268e-07 1.55218e-07" />
<!--                                                            <joint class="joint" name="j_14_right" />-->
                                                        <geom type="mesh" contype="0" conaffinity="0" group="1" rgba="0.792157 0.819608 0.933333 1" mesh="finger_14_right" />
                                                        <geom type="mesh" rgba="0.792157 0.819608 0.933333 1" mesh="finger_14_right" />
                                                    </body>
                                                </body>
                                            </body>
                                        </body>
                                        <body name="finger_21_right" pos="-0.02313 -2.8663e-05 0.10261" quat="-0.00170588 0.14653 -0.0114914 -0.989138">
                                            <inertial pos="-3.24188e-08 -2.51413e-07 0.0147548" quat="0.706869 4.57171e-06 -4.57478e-06 0.707344" mass="0.00477507" diaginertia="5.13037e-07 5.06539e-07 1.11818e-07" />
<!--                                                <joint class="joint" name="j_21_right" />-->
                                            <geom type="mesh" contype="0" conaffinity="0" group="1" rgba="0.792157 0.819608 0.933333 1" mesh="finger_21_right" />
                                            <geom type="mesh" rgba="0.792157 0.819608 0.933333 1" mesh="finger_21_right" />
                                            <body name="finger_22_right" pos="0 0 0.028233" quat="0.999999 0.001304 0 0">
                                                <inertial pos="0 0 0.0105" mass="0.00239726" diaginertia="1.69655e-07 1.65763e-07 9.58619e-08" />
<!--                                                    <joint class="joint" name="j_22_right" />-->
                                                <geom type="mesh" contype="0" conaffinity="0" group="1" rgba="0.792157 0.819608 0.933333 1" mesh="finger_22_right" />
                                                <geom type="mesh" rgba="0.792157 0.819608 0.933333 1" mesh="finger_22_right" />
                                                <body name="finger_23_right" pos="0 0 0.021" quat="0.999026 0.0441192 0 0">
                                                    <inertial pos="1.85149e-05 -3.04051e-05 0.0092181" quat="0.713348 0.00165559 0.000484126 0.700808" mass="0.00351083" diaginertia="2.40712e-07 2.34318e-07 7.61094e-08" />
<!--                                                        <joint class="joint" name="j_23_right" />-->
                                                    <geom type="mesh" contype="0" conaffinity="0" group="1" rgba="0.792157 0.819608 0.933333 1" mesh="finger_23_right" />
                                                    <geom type="mesh" rgba="0.792157 0.819608 0.933333 1" mesh="finger_23_right" />
                                                </body>
                                            </body>
                                        </body>
                                        <body name="finger_31_right" pos="-0.003285 -4.5506e-05 0.10551" quat="-3.67258e-06 -6.77539e-08 -0.0184455 -0.99983">
                                            <inertial pos="-3.39863e-08 -2.51284e-07 0.0147548" quat="0.706871 4.57009e-06 -4.57313e-06 0.707342" mass="0.00477507" diaginertia="5.13037e-07 5.06539e-07 1.11818e-07" />
<!--                                                <joint class="joint" name="j_31_right" />-->
                                            <geom type="mesh" contype="0" conaffinity="0" group="1" rgba="0.792157 0.819608 0.933333 1" mesh="finger_31_right" />
                                            <geom type="mesh" rgba="0.792157 0.819608 0.933333 1" mesh="finger_31_right" />
                                            <body name="finger_32_right" pos="0 0 0.028233" quat="0.999949 0.0101153 0 0">
                                                <inertial pos="0 0 0.0125" mass="0.00316954" diaginertia="2.43247e-07 2.35819e-07 1.2078e-07" />
<!--                                                    <joint class="joint" name="j_32_right" />-->
                                                <geom type="mesh" contype="0" conaffinity="0" group="1" rgba="0.792157 0.819608 0.933333 1" mesh="finger_32_right" />
                                                <geom type="mesh" rgba="0.792157 0.819608 0.933333 1" mesh="finger_32_right" />
                                                <body name="finger_33_right" pos="0 0 0.025" quat="0.999542 -0.0302699 0 0">
                                                    <inertial pos="1.96253e-05 -3.05034e-05 0.0109935" quat="0.713622 0.0013122 0.00048852 0.70053" mass="0.00407939" diaginertia="3.4499e-07 3.3759e-07 9.02118e-08" />
<!--                                                        <joint class="joint" name="j_33_right" />-->
                                                    <geom type="mesh" contype="0" conaffinity="0" group="1" rgba="0.792157 0.819608 0.933333 1" mesh="finger_33_right" />
                                                    <geom type="mesh" rgba="0.792157 0.819608 0.933333 1" mesh="finger_33_right" />
                                                </body>
                                            </body>
                                        </body>
                                        <body name="finger_41_right" pos="0.015838 -1.4117e-05 0.10369" quat="-0.000562628 0.097747 0.00569144 0.995195">
                                            <inertial pos="-3.23356e-08 -2.51413e-07 0.0147548" quat="0.706869 4.5718e-06 -4.57488e-06 0.707344" mass="0.00477507" diaginertia="5.13037e-07 5.06539e-07 1.11818e-07" />
<!--                                                <joint class="joint" name="j_41_right" />-->
                                            <geom type="mesh" contype="0" conaffinity="0" group="1" rgba="0.792157 0.819608 0.933333 1" mesh="finger_41_right" />
                                            <geom type="mesh" rgba="0.792157 0.819608 0.933333 1" mesh="finger_41_right" />
                                            <body name="finger_42_right" pos="0 0 0.028233" quat="0.999279 -0.0379669 0 0">
                                                <inertial pos="0 0 0.011" mass="0.00259033" diaginertia="1.86013e-07 1.81238e-07 1.02092e-07" />
<!--                                                    <joint class="joint" name="j_42_right" />-->
                                                <geom type="mesh" contype="0" conaffinity="0" group="1" rgba="0.792157 0.819608 0.933333 1" mesh="finger_42_right" />
                                                <geom type="mesh" rgba="0.792157 0.819608 0.933333 1" mesh="finger_42_right" />
                                                <body name="finger_43_right" pos="0 0 0.022" quat="0.999968 0.00801491 0 0">
                                                    <inertial pos="1.83811e-05 -3.04115e-05 0.0092181" quat="0.713529 0.00165383 0.000482434 0.700624" mass="0.00351084" diaginertia="2.40711e-07 2.34319e-07 7.61093e-08" />
<!--                                                        <joint class="joint" name="j_43_right" />-->
                                                    <geom type="mesh" contype="0" conaffinity="0" group="1" rgba="0.792157 0.819608 0.933333 1" mesh="finger_43_right" />
                                                    <geom type="mesh" rgba="0.792157 0.819608 0.933333 1" mesh="finger_43_right" />
                                                </body>
                                            </body>
                                        </body>
                                        <body name="finger_51_right" pos="0.032204 7.2479e-05 0.099742" quat="0.00415502 0.141408 -0.0291001 0.989515">
                                            <inertial pos="-3.37018e-08 -2.63901e-07 0.0147548" quat="0.706874 4.61041e-06 -4.61345e-06 0.70734" mass="0.00477507" diaginertia="5.13037e-07 5.06539e-07 1.11818e-07" />
<!--                                                <joint class="joint" name="j_51_right" />-->
                                            <geom type="mesh" contype="0" conaffinity="0" group="1" rgba="0.792157 0.819608 0.933333 1" mesh="finger_51_right" />
                                            <geom type="mesh" rgba="0.792157 0.819608 0.933333 1" mesh="finger_51_right" />
                                            <body name="finger_52_right" pos="0 0 0.028233" quat="0.998235 0.05939 0 0">
                                                <inertial pos="0 0 0.01" mass="0.00220419" diaginertia="1.54494e-07 1.51487e-07 8.96323e-08" />
<!--                                                    <joint class="joint" name="j_52_right" />-->
                                                <geom type="mesh" contype="0" conaffinity="0" group="1" rgba="0.792157 0.819608 0.933333 1" mesh="finger_52_right" />
                                                <geom type="mesh" rgba="0.792157 0.819608 0.933333 1" mesh="finger_52_right" />
                                                <body name="finger_53_right" pos="0 0 0.02" quat="0.99979 -0.0204711 0 0">
                                                    <inertial pos="1.7743e-05 -3.12533e-05 0.00785414" quat="0.712265 0.0020625 0.000429525 0.701908" mass="0.00308471" diaginertia="1.78799e-07 1.73044e-07 6.55991e-08" />
<!--                                                        <joint class="joint" name="j_53_right" />-->
                                                    <geom type="mesh" contype="0" conaffinity="0" group="1" rgba="0.792157 0.819608 0.933333 1" mesh="finger_53_right" />
                                                    <geom type="mesh" rgba="0.792157 0.819608 0.933333 1" mesh="finger_53_right" />
                                                </body>
                                            </body>
                                        </body>
                                    </body>
                                </body>
                            </body>
                        </body>
                    </body>
                </body>
            </body>
            <body name="neck" pos="-0.016175 0 0.515" quat="0.707105 0 0 -0.707108">
                <inertial pos="2.88789e-08 -8.65281e-09 0.0265816" quat="0.49928 0.499347 0.500725 0.500646" mass="0.0321665" diaginertia="7.22266e-06 5.20118e-06 5.14644e-06"/>
<!--                <joint class="arm_joint" name="body_neck" axis="0 0 -1" />-->
                <geom type="mesh" contype="0" conaffinity="0" group="1" rgba="0.792157 0.819608 0.933333 1" mesh="neck"/>
                <geom type="mesh" rgba="0.792157 0.819608 0.933333 1" mesh="neck"/>
                <camera mode="fixed" name="robot0_bodyview" pos="0 0.1 0" quat="0.866 0.5 0 0" />
                <body name="head" pos="0.0219999 6.0166e-05 0.03" quat="0.999635 0.0269785 3.68907e-05 0.00136691">
                    <inertial pos="-0.022 0.0152892 0.0648053" quat="0.705981 0.0399037 -0.0399025 0.705979" mass="1.19735" diaginertia="0.00240376 0.00237423 0.00183049"/>
<!--                    <joint class="arm_joint" name="neck_head" axis="-1 0 0" />-->
                    <geom type="mesh" contype="0" conaffinity="0" group="1" rgba="0.792157 0.819608 0.933333 1" mesh="head"/>
                    <geom type="mesh" rgba="0.792157 0.819608 0.933333 1" mesh="head"/>
                </body>
            </body>
        </body>
    </worldbody>

    <contact>
        <exclude body1="body" body2="left_1"/>
        <exclude body1="body" body2="right_1"/>
<!--        <exclude body1="palm_left" body2="finger_11_left"/>-->
<!--        <exclude body1="palm_left" body2="finger_12_left"/>-->
<!--        <exclude body1="palm_left" body2="finger_21_left"/>-->
<!--        <exclude body1="palm_left" body2="finger_31_left"/>-->
<!--        <exclude body1="palm_left" body2="finger_41_left"/>-->
<!--        <exclude body1="palm_left" body2="finger_51_left"/>-->
    </contact>

<!--    <tendon>-->
<!--        <fixed name="j_20_left">-->
<!--          <joint joint="j_22_left" coef="1"/>-->
<!--          <joint joint="j_23_left" coef="1"/>-->
<!--        </fixed>-->
<!--        <fixed name="j_30_left">-->
<!--          <joint joint="j_32_left" coef="1"/>-->
<!--          <joint joint="j_33_left" coef="1"/>-->
<!--        </fixed>-->
<!--        <fixed name="j_40_left">-->
<!--          <joint joint="j_42_left" coef="1"/>-->
<!--          <joint joint="j_43_left" coef="1"/>-->
<!--        </fixed>-->
<!--        <fixed name="j_50_left">-->
<!--          <joint joint="j_52_left" coef="1"/>-->
<!--          <joint joint="j_53_left" coef="1"/>-->
<!--        </fixed>-->
<!--    </tendon>-->

<!--    <actuator>-->
<!--        <position class="arm_joint" name="j1_left_T" joint="left_j1" ctrllimited="true"/>-->
<!--        <position class="arm_joint" name="j2_left_T" joint="left_j2" ctrllimited="true"/>-->
<!--        <position class="arm_joint" name="j3_left_T" joint="left_j3" ctrllimited="true"/>-->
<!--        <position class="arm_joint" name="j4_left_T" joint="left_j4" ctrllimited="true"/>-->
<!--        <position class="arm_joint" name="j5_left_T" joint="left_j5" ctrllimited="true"/>-->
<!--        <position class="arm_joint" name="j6_left_T" joint="left_j6" ctrllimited="true"/>-->
<!--        <position class="arm_joint" name="j7_left_T" joint="left_j7" ctrllimited="true" ctrlrange="-1.57 1.57"/>-->
<!--        <position class="arm_joint" name="j1_right_T" joint="right_j1" ctrllimited="true"/>-->
<!--        <position class="arm_joint" name="j2_right_T" joint="right_j2" ctrllimited="true"/>-->
<!--        <position class="arm_joint" name="j3_right_T" joint="right_j3" ctrllimited="true"/>-->
<!--        <position class="arm_joint" name="j4_right_T" joint="right_j4" ctrllimited="true"/>-->
<!--        <position class="arm_joint" name="j5_right_T" joint="right_j5" ctrllimited="true"/>-->
<!--        <position class="arm_joint" name="j6_right_T" joint="right_j6" ctrllimited="true"/>-->
<!--        <position class="arm_joint" name="j7_right_T" joint="right_j7" ctrllimited="true" ctrlrange="-1.57 1.57"/>-->

<!--        <position class="joint" name="j11_left_T" joint="j_11_left" ctrllimited="true" ctrlrange="0 1.57" />-->
<!--        <position class="joint" name="j12_left_T" joint="j_12_left" ctrllimited="true" ctrlrange="0 1.8" />-->
<!--        <position class="joint" name="j13_left_T" joint="j_13_left" ctrllimited="true" ctrlrange="-1.57 1.57" />-->
<!--        <position class="joint" name="j14_left_T" joint="j_14_left" ctrllimited="true" ctrlrange="0 2.14" />-->
<!--        <position class="joint" name="j21_left_T" joint="j_21_left" ctrllimited="true" ctrlrange="0 1.57" />-->
<!--        <position class="joint" name="j20_left_T" tendon="j_20_left" ctrllimited="true" ctrlrange="0 2.14" />-->
<!--        <position class="joint" name="j31_left_T" joint="j_31_left" ctrllimited="true" ctrlrange="0 1.57" />-->
<!--        <position class="joint" name="j30_left_T" tendon="j_30_left" ctrllimited="true" ctrlrange="0 2.14" />-->
<!--        <position class="joint" name="j41_left_T" joint="j_41_left" ctrllimited="true" ctrlrange="0 1.57" />-->
<!--        <position class="joint" name="j40_left_T" tendon="j_40_left" ctrllimited="true" ctrlrange="0 2.14" />-->
<!--        <position class="joint" name="j51_left_T" joint="j_51_left" ctrllimited="true" ctrlrange="0 1.57" />-->
<!--        <position class="joint" name="j50_left_T" tendon="j_50_left" ctrllimited="true" ctrlrange="0 2.14" />-->

<!--        <position class="joint" name="j11_right_T" joint="j_11_right" ctrllimited="true" />-->
<!--        <position class="joint" name="j12_right_T" joint="j_12_right" ctrllimited="true" ctrlrange="-1.5 1.5" />-->
<!--        <position class="joint" name="j13_right_T" joint="j_13_right" ctrllimited="true" />-->
<!--        <position class="joint" name="j14_right_T" joint="j_14_right" ctrllimited="true" />-->
<!--        <position class="joint" name="j21_right_T" joint="j_21_right" ctrllimited="true" />-->
<!--        <position class="joint" name="j22_right_T" joint="j_22_right" ctrllimited="true" />-->
<!--        <position class="joint" name="j23_right_T" joint="j_23_right" ctrllimited="true" />-->
<!--        <position class="joint" name="j31_right_T" joint="j_31_right" ctrllimited="true" />-->
<!--        <position class="joint" name="j32_right_T" joint="j_32_right" ctrllimited="true" />-->
<!--        <position class="joint" name="j33_right_T" joint="j_33_right" ctrllimited="true" />-->
<!--        <position class="joint" name="j41_right_T" joint="j_41_right" ctrllimited="true" />-->
<!--        <position class="joint" name="j42_right_T" joint="j_42_right" ctrllimited="true" />-->
<!--        <position class="joint" name="j43_right_T" joint="j_43_right" ctrllimited="true" />-->
<!--        <position class="joint" name="j51_right_T" joint="j_51_right" ctrllimited="true" />-->
<!--        <position class="joint" name="j52_right_T" joint="j_52_right" ctrllimited="true" />-->
<!--        <position class="joint" name="j53_right_T" joint="j_53_right" ctrllimited="true" />-->
<!--    </actuator>-->
</mujoco>

