<mujoco model="base">
  <compiler angle="radian" meshdir="meshes/"/>
  <option impratio="20" density="1.2" viscosity="2e-05" cone="elliptic"/>
  <size njmax="5000" nconmax="5000"/>
  <visual>
    <map znear="0.001"/>
  </visual>
  <statistic meansize="0.202396" extent="2.12805" center="-0.375719 0.00164098 0.495218"/>
  <asset>
    <texture type="skybox" builtin="gradient" rgb1="0.9 0.9 1" rgb2="0.2 0.3 0.4" width="256" height="1536"/>
    <texture type="2d" name="texplane" file="/home/kavin/Documents/PycharmProjects/Robosuite/robosuite/models/assets/arenas/../textures/light-gray-floor-tile.png"/>
    <texture type="cube" name="tex-ceramic" file="/home/kavin/Documents/PycharmProjects/Robosuite/robosuite/models/assets/arenas/../textures/ceramic.png"/>
    <texture type="cube" name="tex-steel-brushed" file="/home/kavin/Documents/PycharmProjects/Robosuite/robosuite/models/assets/arenas/../textures/steel-brushed.png"/>
    <texture type="2d" name="tex-light-gray-plaster" file="/home/kavin/Documents/PycharmProjects/Robosuite/robosuite/models/assets/arenas/../textures/light-gray-plaster.png"/>
    <texture type="cube" name="textable" builtin="flat" rgb1="0.5 0.5 0.5" width="512" height="3072"/>
    <texture type="cube" name="cube_redwood" file="/home/kavin/Documents/PycharmProjects/Robosuite/robosuite/models/assets/textures/red-wood.png"/>
    <material name="floorplane" texture="texplane" texuniform="true" texrepeat="2 2" specular="0" shininess="0" reflectance="0.01"/>
    <material name="table_ceramic" texture="tex-ceramic" specular="0.2" shininess="0"/>
    <material name="table_legs_metal" texture="tex-steel-brushed" shininess="0.8" reflectance="0.8"/>
    <material name="walls_mat" texture="tex-light-gray-plaster" texuniform="true" texrepeat="3 3" specular="0.1" shininess="0.1"/>
    <material name="table_mat" texture="textable"/>
    <material name="robot0_Black" shininess="0.25" rgba="0.033102 0.033102 0.033102 1"/>
    <material name="robot0_JointGrey" shininess="0.25" rgba="0.278431 0.278431 0.278431 1"/>
    <material name="robot0_LinkGrey" shininess="0.25" rgba="0.820392 0.820392 0.820392 1"/>
    <material name="robot0_URBlue" shininess="0.25" rgba="0.490196 0.678431 0.8 1"/>
    <material name="cube_redwood_mat" texture="cube_redwood" specular="0.4" shininess="0.1"/>
    <mesh name="robot0_base_vis_0" file="/home/kavin/Documents/PycharmProjects/Robosuite/robosuite/models/assets/robots/ur5e/obj_meshes/base_vis/base_vis_0.obj"/>
    <mesh name="robot0_base_vis_1" file="/home/kavin/Documents/PycharmProjects/Robosuite/robosuite/models/assets/robots/ur5e/obj_meshes/base_vis/base_vis_1.obj"/>
    <mesh name="robot0_forearm_vis_0" file="/home/kavin/Documents/PycharmProjects/Robosuite/robosuite/models/assets/robots/ur5e/obj_meshes/forearm_vis/forearm_vis_0.obj"/>
    <mesh name="robot0_forearm_vis_1" file="/home/kavin/Documents/PycharmProjects/Robosuite/robosuite/models/assets/robots/ur5e/obj_meshes/forearm_vis/forearm_vis_1.obj"/>
    <mesh name="robot0_forearm_vis_2" file="/home/kavin/Documents/PycharmProjects/Robosuite/robosuite/models/assets/robots/ur5e/obj_meshes/forearm_vis/forearm_vis_2.obj"/>
    <mesh name="robot0_forearm_vis_3" file="/home/kavin/Documents/PycharmProjects/Robosuite/robosuite/models/assets/robots/ur5e/obj_meshes/forearm_vis/forearm_vis_3.obj"/>
    <mesh name="robot0_shoulder_vis_0" file="/home/kavin/Documents/PycharmProjects/Robosuite/robosuite/models/assets/robots/ur5e/obj_meshes/shoulder_vis/shoulder_vis_0.obj"/>
    <mesh name="robot0_shoulder_vis_1" file="/home/kavin/Documents/PycharmProjects/Robosuite/robosuite/models/assets/robots/ur5e/obj_meshes/shoulder_vis/shoulder_vis_1.obj"/>
    <mesh name="robot0_shoulder_vis_2" file="/home/kavin/Documents/PycharmProjects/Robosuite/robosuite/models/assets/robots/ur5e/obj_meshes/shoulder_vis/shoulder_vis_2.obj"/>
    <mesh name="robot0_upperarm_vis_0" file="/home/kavin/Documents/PycharmProjects/Robosuite/robosuite/models/assets/robots/ur5e/obj_meshes/upperarm_vis/upperarm_vis_0.obj"/>
    <mesh name="robot0_upperarm_vis_1" file="/home/kavin/Documents/PycharmProjects/Robosuite/robosuite/models/assets/robots/ur5e/obj_meshes/upperarm_vis/upperarm_vis_1.obj"/>
    <mesh name="robot0_upperarm_vis_2" file="/home/kavin/Documents/PycharmProjects/Robosuite/robosuite/models/assets/robots/ur5e/obj_meshes/upperarm_vis/upperarm_vis_2.obj"/>
    <mesh name="robot0_upperarm_vis_3" file="/home/kavin/Documents/PycharmProjects/Robosuite/robosuite/models/assets/robots/ur5e/obj_meshes/upperarm_vis/upperarm_vis_3.obj"/>
    <mesh name="robot0_wrist1_vis_0" file="/home/kavin/Documents/PycharmProjects/Robosuite/robosuite/models/assets/robots/ur5e/obj_meshes/wrist1_vis/wrist1_vis_0.obj"/>
    <mesh name="robot0_wrist1_vis_1" file="/home/kavin/Documents/PycharmProjects/Robosuite/robosuite/models/assets/robots/ur5e/obj_meshes/wrist1_vis/wrist1_vis_1.obj"/>
    <mesh name="robot0_wrist1_vis_2" file="/home/kavin/Documents/PycharmProjects/Robosuite/robosuite/models/assets/robots/ur5e/obj_meshes/wrist1_vis/wrist1_vis_2.obj"/>
    <mesh name="robot0_wrist2_vis_0" file="/home/kavin/Documents/PycharmProjects/Robosuite/robosuite/models/assets/robots/ur5e/obj_meshes/wrist2_vis/wrist2_vis_0.obj"/>
    <mesh name="robot0_wrist2_vis_1" file="/home/kavin/Documents/PycharmProjects/Robosuite/robosuite/models/assets/robots/ur5e/obj_meshes/wrist2_vis/wrist2_vis_1.obj"/>
    <mesh name="robot0_wrist2_vis_2" file="/home/kavin/Documents/PycharmProjects/Robosuite/robosuite/models/assets/robots/ur5e/obj_meshes/wrist2_vis/wrist2_vis_2.obj"/>
    <mesh name="robot0_wrist3_vis" file="/home/kavin/Documents/PycharmProjects/Robosuite/robosuite/models/assets/robots/ur5e/obj_meshes/wrist3_vis/wrist3_vis.obj"/>
    <mesh name="robot0_base" file="/home/kavin/Documents/PycharmProjects/Robosuite/robosuite/models/assets/robots/ur5e/meshes/base.stl"/>
    <mesh name="robot0_shoulder" file="/home/kavin/Documents/PycharmProjects/Robosuite/robosuite/models/assets/robots/ur5e/meshes/shoulder.stl"/>
    <mesh name="robot0_upperarm" file="/home/kavin/Documents/PycharmProjects/Robosuite/robosuite/models/assets/robots/ur5e/meshes/upperarm.stl"/>
    <mesh name="robot0_forearm" file="/home/kavin/Documents/PycharmProjects/Robosuite/robosuite/models/assets/robots/ur5e/meshes/forearm.stl"/>
    <mesh name="robot0_wrist1" file="/home/kavin/Documents/PycharmProjects/Robosuite/robosuite/models/assets/robots/ur5e/meshes/wrist1.stl"/>
    <mesh name="robot0_wrist2" file="/home/kavin/Documents/PycharmProjects/Robosuite/robosuite/models/assets/robots/ur5e/meshes/wrist2.stl"/>
    <mesh name="robot0_wrist3" file="/home/kavin/Documents/PycharmProjects/Robosuite/robosuite/models/assets/robots/ur5e/meshes/wrist3.stl"/>
    <mesh name="mount0_pedestal" file="/home/kavin/Documents/PycharmProjects/Robosuite/robosuite/models/assets/mounts/meshes/rethink_mount/pedestal.stl"/>
    <mesh name="gripper0_robotiq_arg2f_base_link" file="/home/kavin/Documents/PycharmProjects/Robosuite/robosuite/models/assets/grippers/meshes/robotiq_85_gripper/robotiq_arg2f_base_link.stl"/>
    <mesh name="gripper0_robotiq_arg2f_85_outer_knuckle" file="/home/kavin/Documents/PycharmProjects/Robosuite/robosuite/models/assets/grippers/meshes/robotiq_85_gripper/robotiq_arg2f_85_outer_knuckle.stl" scale="0.001 0.001 0.001"/>
    <mesh name="gripper0_robotiq_arg2f_85_outer_finger" file="/home/kavin/Documents/PycharmProjects/Robosuite/robosuite/models/assets/grippers/meshes/robotiq_85_gripper/robotiq_arg2f_85_outer_finger.stl" scale="0.001 0.001 0.001"/>
    <mesh name="gripper0_robotiq_arg2f_85_inner_finger" file="/home/kavin/Documents/PycharmProjects/Robosuite/robosuite/models/assets/grippers/meshes/robotiq_85_gripper/robotiq_arg2f_85_inner_finger.stl" scale="0.001 0.001 0.001"/>
    <mesh name="gripper0_robotiq_arg2f_85_inner_knuckle" file="/home/kavin/Documents/PycharmProjects/Robosuite/robosuite/models/assets/grippers/meshes/robotiq_85_gripper/robotiq_arg2f_85_inner_knuckle.stl" scale="0.001 0.001 0.001"/>
    <mesh name="gripper0_robotiq_arg2f_85_outer_knuckle_vis" file="/home/kavin/Documents/PycharmProjects/Robosuite/robosuite/models/assets/grippers/meshes/robotiq_85_gripper/robotiq_arg2f_85_outer_knuckle_vis.stl" scale="0.001 0.001 0.001"/>
    <mesh name="gripper0_robotiq_arg2f_85_outer_finger_vis" file="/home/kavin/Documents/PycharmProjects/Robosuite/robosuite/models/assets/grippers/meshes/robotiq_85_gripper/robotiq_arg2f_85_outer_finger_vis.stl" scale="0.001 0.001 0.001"/>
    <mesh name="gripper0_robotiq_arg2f_85_inner_finger_vis" file="/home/kavin/Documents/PycharmProjects/Robosuite/robosuite/models/assets/grippers/meshes/robotiq_85_gripper/robotiq_arg2f_85_inner_finger_vis.stl" scale="0.001 0.001 0.001"/>
    <mesh name="gripper0_robotiq_arg2f_85_inner_knuckle_vis" file="/home/kavin/Documents/PycharmProjects/Robosuite/robosuite/models/assets/grippers/meshes/robotiq_85_gripper/robotiq_arg2f_85_inner_knuckle_vis.stl" scale="0.001 0.001 0.001"/>
  </asset>
  <worldbody>
    <geom name="floor" size="3 3 0.125" type="plane" group="1" material="floorplane"/>
    <camera name="frontview" pos="2.6 0 1.45" quat="0.560842 0.430646 0.430646 0.560842"/>
    <camera name="birdview" pos="-0.2 0 3" quat="0.707107 0 0 0.707107"/>
    <camera name="agentview" pos="0.5 0 1.35" quat="0.653098 0.271041 0.271041 0.653098"/>
    <camera name="sideview" pos="-0.0565177 1.27612 1.48796" quat="0.00990507 0.00687796 0.591223 0.806418"/>
    <light pos="1 1 1.5" dir="-0.19245 -0.19245 -0.96225" directional="true" castshadow="false"/>
    <body name="table" pos="0 0 0.775">
      <geom name="table_collision" size="0.4 0.4 0.025" type="box" rgba="0.5 0.5 0 1"/>
      <geom name="table_visual" size="0.4 0.4 0.025" type="box" contype="0" conaffinity="0" group="1" material="table_ceramic"/>
      <geom name="table_leg1_visual" size="0.025 0.3875" pos="0.3 0.3 -0.3875" type="cylinder" contype="0" conaffinity="0" group="1" material="table_legs_metal"/>
      <geom name="table_leg2_visual" size="0.025 0.3875" pos="-0.3 0.3 -0.3875" type="cylinder" contype="0" conaffinity="0" group="1" material="table_legs_metal"/>
      <geom name="table_leg3_visual" size="0.025 0.3875" pos="-0.3 -0.3 -0.3875" type="cylinder" contype="0" conaffinity="0" group="1" material="table_legs_metal"/>
      <geom name="table_leg4_visual" size="0.025 0.3875" pos="0.3 -0.3 -0.3875" type="cylinder" contype="0" conaffinity="0" group="1" material="table_legs_metal"/>
      <site name="table_top" pos="0 0 0.025" size="0.001" rgba="0 0 0 0"/>
    </body>
    <body name="robot0_base" pos="-0.56 0 0.912">
      <geom name="robot0_g0_vis" type="mesh" contype="0" conaffinity="0" group="1" material="robot0_Black" mesh="robot0_base_vis_0"/>
      <geom name="robot0_g1_vis" type="mesh" contype="0" conaffinity="0" group="1" material="robot0_JointGrey" mesh="robot0_base_vis_1"/>
      <geom name="robot0_base_col" type="mesh" rgba="0 0.5 0 1" mesh="robot0_base"/>
      <camera name="robot0_robotview" pos="1 0 0.4" quat="0.653098 0.271041 0.271041 0.653098"/>
      <body name="robot0_shoulder_link" pos="0 0 0.163">
        <joint name="robot0_shoulder_pan_joint" pos="0 0 0" axis="0 0 1" range="-6.28319 6.28319" armature="5" damping="0.001" frictionloss="0.01"/>
        <geom name="robot0_g2_vis" type="mesh" contype="0" conaffinity="0" group="1" material="robot0_URBlue" mesh="robot0_shoulder_vis_0"/>
        <geom name="robot0_g3_vis" type="mesh" contype="0" conaffinity="0" group="1" material="robot0_Black" mesh="robot0_shoulder_vis_1"/>
        <geom name="robot0_g4_vis" type="mesh" contype="0" conaffinity="0" group="1" material="robot0_JointGrey" mesh="robot0_shoulder_vis_2"/>
        <geom name="robot0_shoulder_col" type="mesh" rgba="0 0.5 0 1" mesh="robot0_shoulder"/>
        <body name="robot0_upper_arm_link" pos="0 0.138 0" quat="0.707107 0 0.707107 0">
          <joint name="robot0_shoulder_lift_joint" pos="0 0 0" axis="0 1 0" range="-6.28319 6.28319" armature="2.5" damping="0.001" frictionloss="0.01"/>
          <geom name="robot0_g5_vis" type="mesh" contype="0" conaffinity="0" group="1" material="robot0_LinkGrey" mesh="robot0_upperarm_vis_0"/>
          <geom name="robot0_g6_vis" type="mesh" contype="0" conaffinity="0" group="1" material="robot0_Black" mesh="robot0_upperarm_vis_1"/>
          <geom name="robot0_g7_vis" type="mesh" contype="0" conaffinity="0" group="1" material="robot0_JointGrey" mesh="robot0_upperarm_vis_2"/>
          <geom name="robot0_g8_vis" type="mesh" contype="0" conaffinity="0" group="1" material="robot0_URBlue" mesh="robot0_upperarm_vis_3"/>
          <geom name="robot0_upperarm_col" type="mesh" rgba="0 0.5 0 1" mesh="robot0_upperarm"/>
          <body name="robot0_forearm_link" pos="0 -0.131 0.425">
            <joint name="robot0_elbow_joint" pos="0 0 0" axis="0 1 0" range="-3.14159 3.14159" armature="1.66667" damping="0.001" frictionloss="0.01"/>
            <geom name="robot0_g9_vis" type="mesh" contype="0" conaffinity="0" group="1" material="robot0_URBlue" mesh="robot0_forearm_vis_0"/>
            <geom name="robot0_g10_vis" type="mesh" contype="0" conaffinity="0" group="1" material="robot0_LinkGrey" mesh="robot0_forearm_vis_1"/>
            <geom name="robot0_g11_vis" type="mesh" contype="0" conaffinity="0" group="1" material="robot0_Black" mesh="robot0_forearm_vis_2"/>
            <geom name="robot0_g12_vis" type="mesh" contype="0" conaffinity="0" group="1" material="robot0_JointGrey" mesh="robot0_forearm_vis_3"/>
            <geom name="robot0_forearm_col" type="mesh" rgba="0 0.5 0 1" mesh="robot0_forearm"/>
            <body name="robot0_wrist_1_link" pos="0 0 0.392" quat="0.707107 0 0.707107 0">
              <joint name="robot0_wrist_1_joint" pos="0 0 0" axis="0 1 0" range="-6.28319 6.28319" armature="1.25" damping="0.001" frictionloss="0.01"/>
              <geom name="robot0_g13_vis" type="mesh" contype="0" conaffinity="0" group="1" material="robot0_Black" mesh="robot0_wrist1_vis_0"/>
              <geom name="robot0_g14_vis" type="mesh" contype="0" conaffinity="0" group="1" material="robot0_URBlue" mesh="robot0_wrist1_vis_1"/>
              <geom name="robot0_g15_vis" type="mesh" contype="0" conaffinity="0" group="1" material="robot0_JointGrey" mesh="robot0_wrist1_vis_2"/>
              <geom name="robot0_wrist1_col" type="mesh" rgba="0 0.5 0 1" mesh="robot0_wrist1"/>
              <body name="robot0_wrist_2_link" pos="0 0.127 0">
                <joint name="robot0_wrist_2_joint" pos="0 0 0" axis="0 0 1" range="-6.28319 6.28319" armature="1" damping="0.001" frictionloss="0.01"/>
                <geom name="robot0_g16_vis" type="mesh" contype="0" conaffinity="0" group="1" material="robot0_Black" mesh="robot0_wrist2_vis_0"/>
                <geom name="robot0_g17_vis" type="mesh" contype="0" conaffinity="0" group="1" material="robot0_URBlue" mesh="robot0_wrist2_vis_1"/>
                <geom name="robot0_g18_vis" type="mesh" contype="0" conaffinity="0" group="1" material="robot0_JointGrey" mesh="robot0_wrist2_vis_2"/>
                <geom name="robot0_wrist2_col" type="mesh" rgba="0 0.5 0 1" mesh="robot0_wrist2"/>
                <body name="robot0_wrist_3_link" pos="0 0 0.1">
                  <joint name="robot0_wrist_3_joint" pos="0 0 0" axis="0 1 0" range="-6.28319 6.28319" armature="0.833333" damping="0.001" frictionloss="0.01"/>
                  <geom name="robot0_g19_vis" type="mesh" contype="0" conaffinity="0" group="1" material="robot0_LinkGrey" mesh="robot0_wrist3_vis"/>
                  <geom name="robot0_wrist3_col" type="mesh" rgba="0 0.5 0 1" mesh="robot0_wrist3"/>
                  <geom name="robot0_wrist3_col2" size="0.005 0.005 0.005" pos="0 0.09 0" quat="0.707107 0 0 0.707107" type="box" rgba="0 0.5 0 1"/>
                  <body name="robot0_right_hand" pos="0 0.098 0" quat="0.707107 -0.707107 0 0">
                    <camera name="robot0_eye_in_hand" pos="0.05 0 0" quat="0 0.707107 0.707107 0" fovy="75"/>
                    <body name="gripper0_robotiq_85_adapter_link">
                      <geom name="gripper0_hand_visual" type="mesh" contype="0" conaffinity="0" group="1" rgba="0.1 0.1 0.1 1" mesh="gripper0_robotiq_arg2f_base_link"/>
                      <geom name="gripper0_hand_collision" type="mesh" rgba="0 0 0.5 1" mesh="gripper0_robotiq_arg2f_base_link"/>
                      <site name="gripper0_ft_frame" pos="0 0 0" size="0.01" group="1" rgba="1 0 0 1"/>
                      <body name="gripper0_eef" pos="0 0 0.145" quat="0.707107 0 0 -0.707107">
                        <site name="gripper0_grip_site" pos="0 0 0" size="0.01" group="1" rgba="1 1.40924e-09 0 0.5"/>
                        <site name="gripper0_ee_x" pos="0.1 0 0" quat="0.707105 0 0.707108 0" size="0.005 0.1" group="1" type="cylinder" rgba="1 0 0 0"/>
                        <site name="gripper0_ee_y" pos="0 0.1 0" quat="0.707105 0.707108 0 0" size="0.005 0.1" group="1" type="cylinder" rgba="0 1 0 0"/>
                        <site name="gripper0_ee_z" pos="0 0 0.1" size="0.005 0.1" group="1" type="cylinder" rgba="0 0 1 0"/>
                        <site name="gripper0_grip_site_cylinder" pos="0 0 0" size="0.005 10" group="1" type="cylinder" rgba="0 1 0 0.3"/>
                      </body>
                      <body name="gripper0_left_outer_knuckle" pos="0 -0.0306011 0.054904" quat="0 0 0 1">
                        <joint name="gripper0_finger_joint" pos="0 0 0" axis="1 0 0" range="0 0.8"/>
                        <geom name="gripper0_left_outer_knuckle_visual" type="mesh" contype="0" conaffinity="0" group="1" rgba="0.792157 0.819608 0.933333 1" mesh="gripper0_robotiq_arg2f_85_outer_knuckle_vis"/>
                        <geom name="gripper0_left_outer_knuckle_collision" type="mesh" solref="0.01 0.25" rgba="0 0 0.5 1" mesh="gripper0_robotiq_arg2f_85_outer_knuckle"/>
                        <geom name="gripper0_left_outer_finger_visual" pos="0 0.0315 -0.0041" type="mesh" contype="0" conaffinity="0" group="1" rgba="0.1 0.1 0.1 1" mesh="gripper0_robotiq_arg2f_85_outer_finger_vis"/>
                        <geom name="gripper0_left_outer_finger_collision" pos="0 0.0315 -0.0041" type="mesh" solref="0.01 0.25" rgba="0 0 0.5 1" mesh="gripper0_robotiq_arg2f_85_outer_finger"/>
                        <body name="gripper0_left_inner_finger" pos="0 0.0376 0.043">
                          <joint name="gripper0_left_inner_finger_joint" pos="0 0 0" axis="1 0 0" range="-0.8757 0.8757"/>
                          <geom name="gripper0_left_inner_finger_visual" type="mesh" contype="0" conaffinity="0" group="1" rgba="0.1 0.1 0.1 1" mesh="gripper0_robotiq_arg2f_85_inner_finger_vis"/>
                          <geom name="gripper0_left_inner_finger_collision" type="mesh" solref="0.01 0.25" rgba="0 0 0.5 1" mesh="gripper0_robotiq_arg2f_85_inner_finger"/>
                          <geom name="gripper0_left_fingertip_visual" size="0.011 0.003175 0.01875" pos="0 -0.0220203 0.03242" type="box" contype="0" conaffinity="0" group="1" rgba="0.9 0.9 0.9 1"/>
                          <geom name="gripper0_left_fingertip_collision" size="0.011 0.003175 0.01875" pos="0 -0.0220203 0.03242" type="box" solref="0.01 0.25" rgba="0 0 0.5 1"/>
                          <geom name="gripper0_left_fingerpad_collision" size="0.01 0.001 0.01675" pos="0 -0.0245203 0.03242" type="box" rgba="0 0 0.5 1"/>
                        </body>
                      </body>
                      <body name="gripper0_left_inner_knuckle" pos="0 -0.0127 0.06142" quat="0 0 0 1">
                        <joint name="gripper0_left_inner_knuckle_joint" pos="0 0 0" axis="1 0 0" range="0 0.8757"/>
                        <geom name="gripper0_left_inner_knuckle_visual" type="mesh" contype="0" conaffinity="0" group="1" rgba="0.1 0.1 0.1 1" mesh="gripper0_robotiq_arg2f_85_inner_knuckle_vis"/>
                        <geom name="gripper0_left_inner_knuckle_collision" type="mesh" rgba="0 0 0.5 1" mesh="gripper0_robotiq_arg2f_85_inner_knuckle"/>
                      </body>
                      <body name="gripper0_right_outer_knuckle" pos="0 0.0306011 0.054904">
                        <joint name="gripper0_right_outer_knuckle_joint" pos="0 0 0" axis="1 0 0" range="0 0.8"/>
                        <geom name="gripper0_right_outer_knuckle_visual" type="mesh" contype="0" conaffinity="0" group="1" rgba="0.792157 0.819608 0.933333 1" mesh="gripper0_robotiq_arg2f_85_outer_knuckle_vis"/>
                        <geom name="gripper0_right_outer_knuckle_collision" type="mesh" solref="0.01 0.25" rgba="0 0 0.5 1" mesh="gripper0_robotiq_arg2f_85_outer_knuckle"/>
                        <geom name="gripper0_right_outer_finger_visual" pos="0 0.0315 -0.0041" type="mesh" contype="0" conaffinity="0" group="1" rgba="0.1 0.1 0.1 1" mesh="gripper0_robotiq_arg2f_85_outer_finger_vis"/>
                        <geom name="gripper0_right_outer_finger_collision" pos="0 0.0315 -0.0041" type="mesh" solref="0.01 0.25" rgba="0 0 0.5 1" mesh="gripper0_robotiq_arg2f_85_outer_finger"/>
                        <body name="gripper0_right_inner_finger" pos="0 0.0376 0.043">
                          <joint name="gripper0_right_inner_finger_joint" pos="0 0 0" axis="1 0 0" range="-0.8757 0.8757"/>
                          <geom name="gripper0_right_inner_finger_visual" type="mesh" contype="0" conaffinity="0" group="1" rgba="0.1 0.1 0.1 1" mesh="gripper0_robotiq_arg2f_85_inner_finger_vis"/>
                          <geom name="gripper0_right_inner_finger_collision" type="mesh" solref="0.01 0.25" rgba="0 0 0.5 1" mesh="gripper0_robotiq_arg2f_85_inner_finger"/>
                          <geom name="gripper0_right_fingertip_visual" size="0.011 0.003175 0.01875" pos="0 -0.0220203 0.03242" type="box" contype="0" conaffinity="0" group="1" rgba="0.9 0.9 0.9 1"/>
                          <geom name="gripper0_right_fingertip_collision" size="0.011 0.003175 0.01875" pos="0 -0.0220203 0.03242" type="box" solref="0.01 0.25" rgba="0 0 0.5 1"/>
                          <geom name="gripper0_right_fingerpad_collision" size="0.01 0.001 0.01675" pos="0 -0.0245203 0.03242" type="box" rgba="0 0 0.5 1"/>
                        </body>
                      </body>
                      <body name="gripper0_right_inner_knuckle" pos="0 0.0127 0.06142">
                        <joint name="gripper0_right_inner_knuckle_joint" pos="0 0 0" axis="1 0 0" range="0 0.8757"/>
                        <geom name="gripper0_right_inner_knuckle_visual" type="mesh" contype="0" conaffinity="0" group="1" rgba="0.1 0.1 0.1 1" mesh="gripper0_robotiq_arg2f_85_inner_knuckle_vis"/>
                        <geom name="gripper0_right_inner_knuckle_collision" type="mesh" rgba="0 0 0.5 1" mesh="gripper0_robotiq_arg2f_85_inner_knuckle"/>
                      </body>
                    </body>
                  </body>
                </body>
              </body>
            </body>
          </body>
        </body>
      </body>
      <body name="mount0_base" pos="0 0 0.01">
        <body name="mount0_controller_box">
          <geom name="mount0_controller_box_col" size="0.11 0.2 0.265" pos="-0.325 0 -0.38" type="box" rgba="0.5 0.5 0 1"/>
        </body>
        <body name="mount0_pedestal_feet">
          <geom name="mount0_pedestal_feet_col" size="0.385 0.35 0.155" pos="-0.1225 0 -0.758" type="box" rgba="0.5 0.5 0 1"/>
        </body>
        <body name="mount0_torso">
          <geom name="mount0_torso_vis" size="0.05 0.05 0.05" pos="0 0 -0.05" type="box" contype="0" conaffinity="0" group="1" rgba="0.2 0.2 0.2 1"/>
        </body>
        <body name="mount0_pedestal">
          <geom name="mount0_pedestal_vis" type="mesh" contype="0" conaffinity="0" group="1" rgba="0.2 0.2 0.2 1" mesh="mount0_pedestal"/>
          <geom name="mount0_pedestal_col" size="0.18 0.31" pos="-0.02 0 -0.29" type="cylinder" rgba="0.5 0.5 0 1"/>
        </body>
      </body>
    </body>
    <body name="cube_main">
      <joint name="cube_joint0" type="free"/>
      <geom name="cube_g0" size="0.021731 0.0207011 0.0612104" type="box" friction="0.95 0.95 0.1" solref="0.01 0.5" density="100" rgba="0.5 0 0 1"/>
      <geom name="cube_g0_vis" size="0.021731 0.0207011 0.0612104" type="box" contype="0" conaffinity="0" group="1" mass="0" material="cube_redwood_mat"/>
      <site name="cube_default_site" pos="0 0 0" size="0.002" rgba="1 0 0 1"/>
    </body>
  </worldbody>
  <tendon>
    <fixed name="gripper0_finger2_12_cpl" range="-1 1" stiffness="0.4" springlength="0.001">
      <joint joint="gripper0_finger_joint" coef="1"/>
      <joint joint="gripper0_left_inner_finger_joint" coef="-3"/>
      <joint joint="gripper0_left_inner_knuckle_joint" coef="1"/>
    </fixed>
    <fixed name="gripper0_finger1_12_cpl" range="-1 1" stiffness="0.4" springlength="0.001">
      <joint joint="gripper0_right_outer_knuckle_joint" coef="1"/>
      <joint joint="gripper0_right_inner_finger_joint" coef="-3"/>
      <joint joint="gripper0_right_inner_knuckle_joint" coef="1"/>
    </fixed>
  </tendon>
  <actuator>
    <general name="robot0_torq_j1" joint="robot0_shoulder_pan_joint" ctrlrange="-150 150"/>
    <general name="robot0_torq_j2" joint="robot0_shoulder_lift_joint" ctrlrange="-150 150"/>
    <general name="robot0_torq_j3" joint="robot0_elbow_joint" ctrlrange="-150 150"/>
    <general name="robot0_torq_j4" joint="robot0_wrist_1_joint" ctrlrange="-28 28"/>
    <general name="robot0_torq_j5" joint="robot0_wrist_2_joint" ctrlrange="-28 28"/>
    <general name="robot0_torq_j6" joint="robot0_wrist_3_joint" ctrlrange="-28 28"/>
    <general name="gripper0_finger_1" joint="gripper0_finger_joint" ctrlrange="0 0.8" biastype="affine" gainprm="20 0 0 0 0 0 0 0 0 0" biasprm="0 -20 0 0 0 0 0 0 0 0"/>
    <general name="gripper0_finger_2" joint="gripper0_right_outer_knuckle_joint" ctrlrange="0 0.8" biastype="affine" gainprm="20 0 0 0 0 0 0 0 0 0" biasprm="0 -20 0 0 0 0 0 0 0 0"/>
  </actuator>
  <sensor>
    <force site="gripper0_ft_frame" name="gripper0_force_ee"/>
    <torque site="gripper0_ft_frame" name="gripper0_torque_ee"/>
  </sensor>
</mujoco>
