<mujoco model="hand_right_sim">
<!--    <compiler angle="radian" meshdir="/home/kavin/Documents/RosProjects/robot_ws/src/hand_right_sim/meshes/" />-->
    <compiler angle="radian"/>
    <default>
<!--        <geom density="5.0" />-->
        <default class="joint">
<!--            <joint axis="1 0 0" range="-3.14 3.14" damping="1" limited="true" armature="0.0002" frictionloss="0.01"/>-->
            <position kp="8"/>
        </default>
    </default>

    <size njmax="500" nconmax="100" />
    <asset>
        <mesh name="palm_right" file="meshes/hand_right/palm_right.STL" />
        <mesh name="finger_11_right" file="meshes/hand_right/finger_11_right.STL" />
        <mesh name="finger_12_right" file="meshes/hand_right/finger_12_right.STL" />
        <mesh name="finger_13_right" file="meshes/hand_right/finger_13_right.STL" />
        <mesh name="finger_14_right" file="meshes/hand_right/finger_14_right.STL" />
        <mesh name="finger_21_right" file="meshes/hand_right/finger_21_right.STL" />
        <mesh name="finger_22_right" file="meshes/hand_right/finger_22_right.STL" />
        <mesh name="finger_23_right" file="meshes/hand_right/finger_23_right.STL" />
        <mesh name="finger_31_right" file="meshes/hand_right/finger_31_right.STL" />
        <mesh name="finger_32_right" file="meshes/hand_right/finger_32_right.STL" />
        <mesh name="finger_33_right" file="meshes/hand_right/finger_33_right.STL" />
        <mesh name="finger_41_right" file="meshes/hand_right/finger_41_right.STL" />
        <mesh name="finger_42_right" file="meshes/hand_right/finger_42_right.STL" />
        <mesh name="finger_43_right" file="meshes/hand_right/finger_43_right.STL" />
        <mesh name="finger_51_right" file="meshes/hand_right/finger_51_right.STL" />
        <mesh name="finger_52_right" file="meshes/hand_right/finger_52_right.STL" />
        <mesh name="finger_53_right" file="meshes/hand_right/finger_53_right.STL" />
    </asset>
    <worldbody>
        <body name="palm_right">

            <site name="ft_frame" pos="0 0 0" size="0.01 0.01 0.01" rgba="1 0 0 1" type="sphere" group="1" />
            <body name="eef" pos="0 0.03 0.08" >
                <site name="grip_site" pos="0 0 0" size="0.01 0.01 0.01" rgba="1 0 0 0.5" type="sphere" group="1"/>
                <site name="ee_x" pos="0.1 0 0" size="0.005 .1"  quat="0.707105  0 0.707108 0 " rgba="1 0 0 0" type="cylinder" group="1"/>
                <site name="ee_y" pos="0 0.1 0" size="0.005 .1" quat="0.707105 0.707108 0 0" rgba="0 1 0 0" type="cylinder" group="1"/>
                <site name="ee_z" pos="0 0 0.1" size="0.005 .1" quat="1 0 0 0" rgba="0 0 1 0" type="cylinder" group="1"/>
                <site name="grip_site_cylinder" pos="0 0 0" size="0.008 1" quat="0.707105  0 0.707108 0 " rgba="0 1 0 0.3" type="cylinder" group="1"/>
            </body>

            <inertial pos="0 0 0" mass="0.01" diaginertia="0.001 0.001 0.001"/>
            <geom type="mesh" contype="0" conaffinity="0" group="1" rgba="0.792157 0.819608 0.933333 1" mesh="palm_right" />
            <geom type="mesh" rgba="0.792157 0.819608 0.933333 1" mesh="palm_right" />
            <body name="finger_11_right" pos="-0.033156 0 0.046854" quat="-0.311001 0.357966 -0.577419 -0.664625">
                <inertial pos="0 0 0.00296384" quat="0.707107 0 0 0.707107" mass="0.00158261" diaginertia="6.47978e-08 5.66929e-08 5.56708e-08" />
                <geom type="mesh" contype="0" conaffinity="0" group="1" rgba="0.792157 0.819608 0.933333 1" mesh="finger_11_right" />
                <geom type="mesh" rgba="0.792157 0.819608 0.933333 1" mesh="finger_11_right" />
                <body name="finger_12_right" pos="0 0 0.005" quat="0.787626 0 0 0.616154">
                    <inertial pos="1.34465e-10 -1.6126e-11 0.00925016" quat="0.707107 0 0 0.707107" mass="0.00237615" diaginertia="1.18675e-07 1.15819e-07 1.06634e-07" />
                    <geom type="mesh" contype="0" conaffinity="0" group="1" rgba="0.792157 0.819608 0.933333 1" mesh="finger_12_right" />
                    <geom type="mesh" rgba="0.792157 0.819608 0.933333 1" mesh="finger_12_right" />
                    <body name="finger_13_right" pos="0 0 0.0175">
                        <inertial pos="2.82781e-08 -2.39368e-07 0.0134786" quat="0.70735 -4.56959e-06 4.56645e-06 0.706863" mass="0.00477507" diaginertia="5.13036e-07 5.06539e-07 1.11818e-07" />
                        <joint name="j_13_right" pos="0 0 0" axis="-1 0 0" limited="true" range="0 1.57" damping="0.01" armature="0.0002" frictionloss="0.01" />
                        <geom type="mesh" contype="0" conaffinity="0" group="1" rgba="0.792157 0.819608 0.933333 1" mesh="finger_13_right" />
                        <geom type="mesh" rgba="0.792157 0.819608 0.933333 1" mesh="finger_13_right" />
                        <body name="finger_14_right" pos="0 0 0.027" quat="0.939693 -0.342019 0 0">
                            <inertial pos="1.258e-05 -0.000148503 0.0147394" quat="0.704715 0.00742828 -0.00610749 0.709425" mass="0.0045956" diaginertia="3.58606e-07 3.47268e-07 1.55217e-07" />
                            <geom type="mesh" contype="0" conaffinity="0" group="1" rgba="0.792157 0.819608 0.933333 1" mesh="finger_14_right" />
                            <geom type="mesh" rgba="0.792157 0.819608 0.933333 1" mesh="finger_14_right" />
                        </body>
                    </body>
                </body>
            </body>

            <body name="finger_21_right" pos="-0.023151 -0.00042188 0.10268" quat="0.0254432 -0.144315 0.171775 0.974176">
                <inertial pos="-3.24152e-08 -2.51581e-07 0.0147548" quat="0.706869 4.57535e-06 -4.57842e-06 0.707344" mass="0.00477507" diaginertia="5.13037e-07 5.06539e-07 1.11818e-07"/>
                <joint name="j_21_right" pos="0 0 0" axis="1 0 0" limited="true" range="0 1.57" damping="0.01" armature="0.0002" frictionloss="0.01" />
                <geom type="mesh" contype="0" conaffinity="0" group="1" rgba="0.792157 0.819608 0.933333 1" mesh="finger_21_right"/>
                <geom type="mesh" rgba="0.792157 0.819608 0.933333 1" mesh="finger_21_right"/>
                <body name="finger_22_right" pos="0 0 0.028233" quat="0.999917 0.0129201 0 0">
                    <inertial pos="0 0 0.0105" mass="0.00239726" diaginertia="1.69655e-07 1.65763e-07 9.58619e-08"/>
                    <joint name="j_22_right" pos="0 0 0" axis="1 0 0" limited="true" range="0 1.57" damping="0.01" armature="0.0002" frictionloss="0.01" />
                    <geom type="mesh" contype="0" conaffinity="0" group="1" rgba="0.792157 0.819608 0.933333 1" mesh="finger_22_right"/>
                    <geom type="mesh" rgba="0.792157 0.819608 0.933333 1" mesh="finger_22_right"/>
                    <body name="finger_23_right" pos="0 0 0.021" quat="0.965926 0.25882 0 0">
                        <inertial pos="1.84084e-05 -3.05369e-05 0.00921808" quat="0.713531 0.00165565 0.000480641 0.700622" mass="0.00351081" diaginertia="2.40713e-07 2.34316e-07 7.61095e-08"/>
                        <geom type="mesh" contype="0" conaffinity="0" group="1" rgba="0.792157 0.819608 0.933333 1" mesh="finger_23_right"/>
                        <geom type="mesh" rgba="0.792157 0.819608 0.933333 1" mesh="finger_23_right"/>
                    </body>
                </body>
            </body>

            <body name="finger_31_right" pos="-0.003285 -0.00042188 0.10558" quat="-3.6174e-06 -6.37853e-07 -0.17365 -0.984807">
                <inertial pos="-3.25832e-08 -2.51593e-07 0.0147548" quat="0.70687 4.57531e-06 -4.57838e-06 0.707344" mass="0.00477507" diaginertia="5.13037e-07 5.06539e-07 1.11818e-07"/>
                <joint name="j_31_right" pos="0 0 0" axis="1 0 0" limited="true" range="0 1.57" damping="0.01" armature="0.0002" frictionloss="0.01" />
                <geom type="mesh" contype="0" conaffinity="0" group="1" rgba="0.792157 0.819608 0.933333 1" mesh="finger_31_right"/>
                <geom type="mesh" rgba="0.792157 0.819608 0.933333 1" mesh="finger_31_right"/>
                <body name="finger_32_right" pos="0 0 0.028233" quat="0.999592 0.0285586 0 0">
                    <inertial pos="0 0 0.0125" mass="0.00316954" diaginertia="2.43247e-07 2.35819e-07 1.2078e-07"/>
                    <joint name="j_32_right" pos="0 0 0" axis="1 0 0" limited="true" range="0 1.57" damping="0.01" armature="0.0002" frictionloss="0.01" />
                    <geom type="mesh" contype="0" conaffinity="0" group="1" rgba="0.792157 0.819608 0.933333 1" mesh="finger_32_right"/>
                    <geom type="mesh" rgba="0.792157 0.819608 0.933333 1" mesh="finger_32_right"/>
                    <body name="finger_33_right" pos="0 0 0.025" quat="0.965926 0.25882 0 0">
                        <inertial pos="1.96219e-05 -3.05376e-05 0.0109935" quat="0.713649 0.00131231 0.000487925 0.700502" mass="0.00407938" diaginertia="3.4499e-07 3.3759e-07 9.02118e-08"/>
                        <geom type="mesh" contype="0" conaffinity="0" group="1" rgba="0.792157 0.819608 0.933333 1" mesh="finger_33_right"/>
                        <geom type="mesh" rgba="0.792157 0.819608 0.933333 1" mesh="finger_33_right"/>
                    </body>
                </body>
            </body>

            <body name="finger_41_right" pos="0.015852 -0.00042188 0.10376" quat="-0.0169777 0.096263 0.172819 0.980091">
                <inertial pos="-3.23309e-08 -2.51623e-07 0.0147548" quat="0.706869 4.57568e-06 -4.57875e-06 0.707344" mass="0.00477507" diaginertia="5.13037e-07 5.06539e-07 1.11818e-07"/>
                <joint name="j_41_right" pos="0 0 0" axis="1 0 0" limited="true" range="0 1.57" damping="0.01" armature="0.0002" frictionloss="0.01" />
                <geom type="mesh" contype="0" conaffinity="0" group="1" rgba="0.792157 0.819608 0.933333 1" mesh="finger_41_right"/>
                <geom type="mesh" rgba="0.792157 0.819608 0.933333 1" mesh="finger_41_right"/>
                <body name="finger_42_right" pos="0 0 0.028233" quat="0.99948 -0.0322514 0 0">
                    <inertial pos="0 0 0.011" mass="0.00259033" diaginertia="1.86013e-07 1.81238e-07 1.02092e-07"/>
                    <joint name="j_42_right" pos="0 0 0" axis="1 0 0" limited="true" range="0 1.57" damping="0.01" armature="0.0002" frictionloss="0.01" />
                    <geom type="mesh" contype="0" conaffinity="0" group="1" rgba="0.792157 0.819608 0.933333 1" mesh="finger_42_right"/>
                    <geom type="mesh" rgba="0.792157 0.819608 0.933333 1" mesh="finger_42_right"/>
                    <body name="finger_43_right" pos="0 0 0.022" quat="0.965926 0.25882 0 0">
                        <inertial pos="1.83933e-05 -3.04606e-05 0.00921809" quat="0.713523 0.00165454 0.000481261 0.70063" mass="0.00351083" diaginertia="2.40711e-07 2.34318e-07 7.61094e-08"/>
                        <geom type="mesh" contype="0" conaffinity="0" group="1" rgba="0.792157 0.819608 0.933333 1" mesh="finger_43_right"/>
                        <geom type="mesh" rgba="0.792157 0.819608 0.933333 1" mesh="finger_43_right"/>
                    </body>
                </body>
            </body>

            <body name="finger_51_right" pos="0.032224 -0.00042188 0.099812" quat="-0.0245697 0.139319 0.171904 0.974903">
                <inertial pos="-3.23106e-08 -2.51629e-07 0.0147548" quat="0.706869 4.57573e-06 -4.57881e-06 0.707344" mass="0.00477507" diaginertia="5.13037e-07 5.06539e-07 1.11818e-07"/>
                <joint name="j_51_right" pos="0 0 0" axis="1 0 0" limited="true" range="0 1.57" damping="0.01" armature="0.0002" frictionloss="0.01" />
                <geom type="mesh" contype="0" conaffinity="0" group="1" rgba="0.792157 0.819608 0.933333 1" mesh="finger_51_right"/>
                <geom type="mesh" rgba="0.792157 0.819608 0.933333 1" mesh="finger_51_right"/>
                <body name="finger_52_right" pos="0 0 0.028233" quat="0.999549 0.0300175 0 0">
                    <inertial pos="0 0 0.01" mass="0.00220419" diaginertia="1.54494e-07 1.51487e-07 8.96323e-08"/>
                    <joint name="j_52_right" pos="0 0 0" axis="1 0 0" limited="true" range="0 1.57" damping="0.01" armature="0.0002" frictionloss="0.01" />
                    <geom type="mesh" contype="0" conaffinity="0" group="1" rgba="0.792157 0.819608 0.933333 1" mesh="finger_52_right"/>
                    <geom type="mesh" rgba="0.792157 0.819608 0.933333 1" mesh="finger_52_right"/>
                    <body name="finger_53_right" pos="0 0 0.02" quat="0.965926 0.25882 0 0">
                        <inertial pos="1.77714e-05 -3.13552e-05 0.00785411" quat="0.71222 0.00206589 0.000426732 0.701954" mass="0.0030847" diaginertia="1.78801e-07 1.73041e-07 6.55997e-08"/>
                        <geom type="mesh" contype="0" conaffinity="0" group="1" rgba="0.792157 0.819608 0.933333 1" mesh="finger_53_right"/>
                        <geom type="mesh" rgba="0.792157 0.819608 0.933333 1" mesh="finger_53_right"/>
                    </body>
                </body>
            </body>

        </body>
    </worldbody>

    <contact>
        <exclude body1="palm_right" body2="finger_11_right"/>
        <exclude body1="palm_right" body2="finger_12_right"/>
        <exclude body1="palm_right" body2="finger_21_right"/>
        <exclude body1="palm_right" body2="finger_31_right"/>
        <exclude body1="palm_right" body2="finger_41_right"/>
        <exclude body1="palm_right" body2="finger_51_right"/>
    </contact>

    <tendon>
        <fixed name="j_20_right">
          <joint joint="j_21_right" coef="1"/>
          <joint joint="j_22_right" coef="1"/>
        </fixed>
        <fixed name="j_30_right">
          <joint joint="j_31_right" coef="1"/>
          <joint joint="j_32_right" coef="1"/>
        </fixed>
        <fixed name="j_40_right">
          <joint joint="j_41_right" coef="1"/>
          <joint joint="j_42_right" coef="1"/>
        </fixed>
        <fixed name="j_50_right">
          <joint joint="j_51_right" coef="1"/>
          <joint joint="j_52_right" coef="1"/>
        </fixed>
    </tendon>

<!--    <equality>-->
<!--        <tendon name="j_20_right" tendon1="j_20_right"/>-->
<!--        <tendon name="j_30_right" tendon1="j_30_right"/>-->
<!--        <tendon name="j_40_right" tendon1="j_40_right"/>-->
<!--        <tendon name="j_50_right" tendon1="j_50_right"/>-->
<!--    </equality>-->

    <actuator>
        <position class="joint" name="j13_right_T" joint="j_13_right" ctrllimited="true" ctrlrange="0. 0.4" />
        <position class="joint" name="j20_right_T" tendon="j_20_right" ctrllimited="true" ctrlrange="0. 1.57" />
        <position class="joint" name="j30_right_T" tendon="j_30_right" ctrllimited="true" ctrlrange="0. 1.57" />
        <position class="joint" name="j40_right_T" tendon="j_40_right" ctrllimited="true" ctrlrange="0. 1.57" />
        <position class="joint" name="j50_right_T" tendon="j_50_right" ctrllimited="true" ctrlrange="0. 1.57" />

    </actuator>
    <sensor>
        <force name="force_ee" site="ft_frame"/>
        <torque name="torque_ee" site="ft_frame"/>
    </sensor>
</mujoco>
